Traceback (most recent call last):
  File "C:\Users\Domen\AppData\Local\Programs\Python\Python312\Lib\site-packages\jupyter_cache\executors\utils.py", line 58, in single_nb_execution
    executenb(
  File "C:\Users\Domen\AppData\Local\Programs\Python\Python312\Lib\site-packages\nbclient\client.py", line 1314, in execute
    return NotebookClient(nb=nb, resources=resources, km=km, **kwargs).execute()
           ^^^^^^^^^^^^^^^^^^^^^^^^^^^^^^^^^^^^^^^^^^^^^^^^^^^^^^^^^^^^^^^^^^^^^
  File "C:\Users\Domen\AppData\Local\Programs\Python\Python312\Lib\site-packages\jupyter_core\utils\__init__.py", line 165, in wrapped
    return loop.run_until_complete(inner)
           ^^^^^^^^^^^^^^^^^^^^^^^^^^^^^^
  File "C:\Users\Domen\AppData\Local\Programs\Python\Python312\Lib\asyncio\base_events.py", line 685, in run_until_complete
    return future.result()
           ^^^^^^^^^^^^^^^
  File "C:\Users\Domen\AppData\Local\Programs\Python\Python312\Lib\site-packages\nbclient\client.py", line 709, in async_execute
    await self.async_execute_cell(
  File "C:\Users\Domen\AppData\Local\Programs\Python\Python312\Lib\site-packages\nbclient\client.py", line 1062, in async_execute_cell
    await self._check_raise_for_error(cell, cell_index, exec_reply)
  File "C:\Users\Domen\AppData\Local\Programs\Python\Python312\Lib\site-packages\nbclient\client.py", line 918, in _check_raise_for_error
    raise CellExecutionError.from_cell_and_msg(cell, exec_reply_content)
nbclient.exceptions.CellExecutionError: An error occurred while executing the following cell:
------------------
import os
import numpy as np
import matplotlib
matplotlib.use('Agg')

import matplotlib.pyplot as plt
import matplotlib.patches as patches
from matplotlib.animation import FuncAnimation
from ipywidgets import interact
from mpl_toolkits.axes_grid1.inset_locator import zoomed_inset_axes, mark_inset
import warnings
warnings.filterwarnings('ignore')

import lvm_read
import pyFRF
import pyidi
import pyEMA
------------------


[1;31m---------------------------------------------------------------------------[0m
[1;31mModuleNotFoundError[0m                       Traceback (most recent call last)
Cell [1;32mIn[1], line 16[0m
[0;32m     14[0m [38;5;28;01mimport[39;00m [38;5;21;01mlvm_read[39;00m
[0;32m     15[0m [38;5;28;01mimport[39;00m [38;5;21;01mpyFRF[39;00m
[1;32m---> 16[0m [38;5;28;01mimport[39;00m [38;5;21;01mpyidi[39;00m
[0;32m     17[0m [38;5;28;01mimport[39;00m [38;5;21;01mpyEMA[39;00m

[1;31mModuleNotFoundError[0m: No module named 'pyidi'

