Traceback (most recent call last):
  File "d:\pedago≈°ko\_Procesiranje signalov\_VAJE\ps_lv\venv\lib\site-packages\jupyter_cache\executors\utils.py", line 58, in single_nb_execution
    executenb(
  File "d:\pedago≈°ko\_Procesiranje signalov\_VAJE\ps_lv\venv\lib\site-packages\nbclient\client.py", line 1204, in execute
    return NotebookClient(nb=nb, resources=resources, km=km, **kwargs).execute()
  File "d:\pedago≈°ko\_Procesiranje signalov\_VAJE\ps_lv\venv\lib\site-packages\nbclient\util.py", line 84, in wrapped
    return just_run(coro(*args, **kwargs))
  File "d:\pedago≈°ko\_Procesiranje signalov\_VAJE\ps_lv\venv\lib\site-packages\nbclient\util.py", line 62, in just_run
    return loop.run_until_complete(coro)
  File "C:\Users\Domen\AppData\Local\Programs\Python\Python310\lib\asyncio\base_events.py", line 641, in run_until_complete
    return future.result()
  File "d:\pedago≈°ko\_Procesiranje signalov\_VAJE\ps_lv\venv\lib\site-packages\nbclient\client.py", line 663, in async_execute
    await self.async_execute_cell(
  File "d:\pedago≈°ko\_Procesiranje signalov\_VAJE\ps_lv\venv\lib\site-packages\nbclient\client.py", line 965, in async_execute_cell
    await self._check_raise_for_error(cell, cell_index, exec_reply)
  File "d:\pedago≈°ko\_Procesiranje signalov\_VAJE\ps_lv\venv\lib\site-packages\nbclient\client.py", line 862, in _check_raise_for_error
    raise CellExecutionError.from_cell_and_msg(cell, exec_reply_content)
nbclient.exceptions.CellExecutionError: An error occurred while executing the following cell:
------------------
import os
import numpy as np
import matplotlib
matplotlib.use('Agg')

import matplotlib.pyplot as plt
import matplotlib.patches as patches
from matplotlib.animation import FuncAnimation
from ipywidgets import interact
from mpl_toolkits.axes_grid1.inset_locator import zoomed_inset_axes, mark_inset
import warnings
warnings.filterwarnings('ignore')

import lvm_read
import pyFRF
import pyidi
import pyEMA
------------------

[1;31m---------------------------------------------------------------------------[0m
[1;31mModuleNotFoundError[0m                       Traceback (most recent call last)
Input [1;32mIn [1][0m, in [0;36m<cell line: 15>[1;34m()[0m
[0;32m     12[0m warnings[38;5;241m.[39mfilterwarnings([38;5;124m'[39m[38;5;124mignore[39m[38;5;124m'[39m)
[0;32m     14[0m [38;5;28;01mimport[39;00m [38;5;21;01mlvm_read[39;00m
[1;32m---> 15[0m [38;5;28;01mimport[39;00m [38;5;21;01mpyFRF[39;00m
[0;32m     16[0m [38;5;28;01mimport[39;00m [38;5;21;01mpyidi[39;00m
[0;32m     17[0m [38;5;28;01mimport[39;00m [38;5;21;01mpyEMA[39;00m

[1;31mModuleNotFoundError[0m: No module named 'pyFRF'
ModuleNotFoundError: No module named 'pyFRF'

