Traceback (most recent call last):
  File "C:\Users\Domen\AppData\Local\Programs\Python\Python310\lib\site-packages\jupyter_cache\executors\utils.py", line 51, in single_nb_execution
    executenb(
  File "C:\Users\Domen\AppData\Local\Programs\Python\Python310\lib\site-packages\nbclient\client.py", line 1093, in execute
    return NotebookClient(nb=nb, resources=resources, km=km, **kwargs).execute()
  File "C:\Users\Domen\AppData\Local\Programs\Python\Python310\lib\site-packages\nbclient\util.py", line 84, in wrapped
    return just_run(coro(*args, **kwargs))
  File "C:\Users\Domen\AppData\Local\Programs\Python\Python310\lib\site-packages\nbclient\util.py", line 62, in just_run
    return loop.run_until_complete(coro)
  File "C:\Users\Domen\AppData\Local\Programs\Python\Python310\lib\asyncio\base_events.py", line 641, in run_until_complete
    return future.result()
  File "C:\Users\Domen\AppData\Local\Programs\Python\Python310\lib\site-packages\nbclient\client.py", line 559, in async_execute
    await self.async_execute_cell(
  File "C:\Users\Domen\AppData\Local\Programs\Python\Python310\lib\site-packages\nbclient\client.py", line 854, in async_execute_cell
    self._check_raise_for_error(cell, exec_reply)
  File "C:\Users\Domen\AppData\Local\Programs\Python\Python310\lib\site-packages\nbclient\client.py", line 756, in _check_raise_for_error
    raise CellExecutionError.from_cell_and_msg(cell, exec_reply_content)
nbclient.exceptions.CellExecutionError: An error occurred while executing the following cell:
------------------
file_2 = 'data/03/test_segments.lvm'
loaded_data_2 = lvm_read.read(file_2)
loaded_data_2['Segments']
------------------

[1;31m---------------------------------------------------------------------------[0m
[1;31mFileNotFoundError[0m                         Traceback (most recent call last)
[1;32m~\AppData\Local\Temp/ipykernel_1192/2970992039.py[0m in [0;36m<module>[1;34m[0m
[0;32m      1[0m [0mfile_2[0m [1;33m=[0m [1;34m'data/03/test_segments.lvm'[0m[1;33m[0m[1;33m[0m[0m
[1;32m----> 2[1;33m [0mloaded_data_2[0m [1;33m=[0m [0mlvm_read[0m[1;33m.[0m[0mread[0m[1;33m([0m[0mfile_2[0m[1;33m)[0m[1;33m[0m[1;33m[0m[0m
[0m[0;32m      3[0m [0mloaded_data_2[0m[1;33m[[0m[1;34m'Segments'[0m[1;33m][0m[1;33m[0m[1;33m[0m[0m

[1;32m~\AppData\Local\Programs\Python\Python310\lib\site-packages\lvm_read.py[0m in [0;36mread[1;34m(filename, read_from_pickle, dump_file)[0m
[0;32m    200[0m         [1;32mreturn[0m [0mlvm_data[0m[1;33m[0m[1;33m[0m[0m
[0;32m    201[0m     [1;32melse[0m[1;33m:[0m[1;33m[0m[1;33m[0m[0m
[1;32m--> 202[1;33m         [0mlvm_data[0m [1;33m=[0m [0m_read_lvm_base[0m[1;33m([0m[0mfilename[0m[1;33m)[0m[1;33m[0m[1;33m[0m[0m
[0m[0;32m    203[0m         [1;32mif[0m [0mdump_file[0m[1;33m:[0m[1;33m[0m[1;33m[0m[0m
[0;32m    204[0m             [0m_lvm_dump[0m[1;33m([0m[0mlvm_data[0m[1;33m,[0m [0mfilename[0m[1;33m)[0m[1;33m[0m[1;33m[0m[0m

[1;32m~\AppData\Local\Programs\Python\Python310\lib\site-packages\lvm_read.py[0m in [0;36m_read_lvm_base[1;34m(filename)[0m
[0;32m     71[0m     [1;33m:[0m[1;32mreturn[0m [0mlvm_data[0m[1;33m:[0m [0mlvm[0m [0mdict[0m[1;33m[0m[1;33m[0m[0m
[0;32m     72[0m     """
[1;32m---> 73[1;33m     [1;32mwith[0m [0mopen[0m[1;33m([0m[0mfilename[0m[1;33m,[0m [1;34m'r'[0m[1;33m,[0m [0mencoding[0m[1;33m=[0m[1;34m"utf8"[0m[1;33m,[0m [0merrors[0m[1;33m=[0m[1;34m'ignore'[0m[1;33m)[0m [1;32mas[0m [0mf[0m[1;33m:[0m[1;33m[0m[1;33m[0m[0m
[0m[0;32m     74[0m         [0mlvm_data[0m [1;33m=[0m [0mread_lines[0m[1;33m([0m[0mf[0m[1;33m)[0m[1;33m[0m[1;33m[0m[0m
[0;32m     75[0m     [1;32mreturn[0m [0mlvm_data[0m[1;33m[0m[1;33m[0m[0m

[1;31mFileNotFoundError[0m: [Errno 2] No such file or directory: 'data/03/test_segments.lvm'
FileNotFoundError: [Errno 2] No such file or directory: 'data/03/test_segments.lvm'

